Traceback (most recent call last):
  File "/usr/lib64/python2.6/logging/handlers.py", line 77, in emit
    self.doRollover()
  File "/usr/lib64/python2.6/logging/handlers.py", line 134, in doRollover
    os.rename(self.baseFilename, dfn)
OSError: [Errno 2] No such file or directory
Traceback (most recent call last):
  File "/usr/lib64/python2.6/logging/handlers.py", line 76, in emit
    if self.shouldRollover(record):
  File "/usr/lib64/python2.6/logging/handlers.py", line 150, in shouldRollover
    self.stream.seek(0, 2)  #due to non-posix-compliant Windows feature
ValueError: I/O operation on closed file
Error in atexit._run_exitfuncs:
Traceback (most recent call last):
  File "/usr/lib64/python2.6/atexit.py", line 24, in _run_exitfuncs
    func(*targs, **kargs)
  File "/usr/lib64/python2.6/logging/__init__.py", line 1516, in shutdown
    h.flush()
  File "/usr/lib64/python2.6/logging/__init__.py", line 762, in flush
    self.stream.flush()
ValueError: I/O operation on closed file
Error in sys.exitfunc:
Traceback (most recent call last):
  File "/usr/lib64/python2.6/atexit.py", line 24, in _run_exitfuncs
    func(*targs, **kargs)
  File "/usr/lib64/python2.6/logging/__init__.py", line 1516, in shutdown
    h.flush()
  File "/usr/lib64/python2.6/logging/__init__.py", line 762, in flush
    self.stream.flush()
ValueError: I/O operation on closed file

INFO 	2016-01-11 09:55:49 	[quantification_kallisto] 	performing pseudoalignment and quantifying abundances of transcripts using kallisto
INFO 	2016-01-11 09:55:49 	[quantification_kallisto] 	using Ensemble genes as transcriptome reference
INFO 	2016-01-11 15:02:32 	[quantification_kallisto] 	converting form HDF5 to text
INFO 	2016-01-11 15:03:35 	[quantification_kallisto] 	quantifications are in /users/GR/mb/jquilez/data/rnaseq/samples/siPADI2-R6h-R2/quantifications/kallisto
TIME 	2016-01-11 15:03:35 	[quantification_kallisto] 	step time for completion (seconds) = 18466


